Traceback (most recent call last):
  File "/workspace/.pyenv_mirror/user/current/lib/python3.12/site-packages/jupyter_cache/executors/utils.py", line 58, in single_nb_execution
    executenb(
  File "/home/gitpod/.pyenv/versions/3.12.3/lib/python3.12/site-packages/nbclient/client.py", line 1314, in execute
    return NotebookClient(nb=nb, resources=resources, km=km, **kwargs).execute()
           ^^^^^^^^^^^^^^^^^^^^^^^^^^^^^^^^^^^^^^^^^^^^^^^^^^^^^^^^^^^^^^^^^^^^^
  File "/home/gitpod/.pyenv/versions/3.12.3/lib/python3.12/site-packages/jupyter_core/utils/__init__.py", line 165, in wrapped
    return loop.run_until_complete(inner)
           ^^^^^^^^^^^^^^^^^^^^^^^^^^^^^^
  File "/home/gitpod/.pyenv/versions/3.12.3/lib/python3.12/asyncio/base_events.py", line 687, in run_until_complete
    return future.result()
           ^^^^^^^^^^^^^^^
  File "/home/gitpod/.pyenv/versions/3.12.3/lib/python3.12/site-packages/nbclient/client.py", line 709, in async_execute
    await self.async_execute_cell(
  File "/home/gitpod/.pyenv/versions/3.12.3/lib/python3.12/site-packages/nbclient/client.py", line 1062, in async_execute_cell
    await self._check_raise_for_error(cell, cell_index, exec_reply)
  File "/home/gitpod/.pyenv/versions/3.12.3/lib/python3.12/site-packages/nbclient/client.py", line 918, in _check_raise_for_error
    raise CellExecutionError.from_cell_and_msg(cell, exec_reply_content)
nbclient.exceptions.CellExecutionError: An error occurred while executing the following cell:
------------------
# mount your Google drive to the "mnt/" mount point
from google.colab import drive
drive.flush_and_unmount()
drive.mount("mnt")
------------------


[0;31m---------------------------------------------------------------------------[0m
[0;31mModuleNotFoundError[0m                       Traceback (most recent call last)
Cell [0;32mIn[2], line 2[0m
[1;32m      1[0m [38;5;66;03m# mount your Google drive to the "mnt/" mount point[39;00m
[0;32m----> 2[0m [38;5;28;01mfrom[39;00m [38;5;21;01mgoogle[39;00m[38;5;21;01m.[39;00m[38;5;21;01mcolab[39;00m [38;5;28;01mimport[39;00m drive
[1;32m      3[0m drive[38;5;241m.[39mflush_and_unmount()
[1;32m      4[0m drive[38;5;241m.[39mmount([38;5;124m"[39m[38;5;124mmnt[39m[38;5;124m"[39m)

[0;31mModuleNotFoundError[0m: No module named 'google'

